# Hard Work - Прекратите вызывать throw/raise

## Пример 1

Класс `Register` для хранения данных - представляет собой простую обёртку над словарём.
try-except используется для управления получением или удалением значений.

```python
class Register:
    def __init__(self, dict_: dict) -> None:
        for k, v in dict_.items():
            self._validate_key_value(k, v)
        self.__data = dict_

    def __getitem__(self, key: int) -> int:
        self._validate_key_value(key, 0)
        try:
            return self.__data[key]
        except KeyError:
            raise RegisterError("Trying to get non-existing value from register")

    def __delitem__(self, key: int):
        self._validate_key_value(key, 0)
        try:
            del self.__data[key]
        except RegisterError:
            raise RegisterError("Trying to delete non-existing value from register")
```

Да, может быть разумно использовать специальное исключение `RegisterError`, однако при управлении элементами оно кажется
не совсем передаёт правильную информацию. Достаточно было бы просто отдать `Python` возможность выбросить исключение `KeyError`
которое ясно говорит о том, что пошло не так:

```python
def __getitem__(self, key: int) -> int:
    self._validate_key_value(key, 0)
    # KeyError
    return self.__data[key]

def __delitem__(self, key: int):
    self._validate_key_value(key, 0)
    # KeyError
    del self.__data[key]
```

## Пример 2

Имеем функцию, которая распараллеливает обращение в БД для распределения нагрузки.
Обработка исключений из тредов происходит как раз с помощью `try-except`. Хотя мне кажется,
что это в целом более-менее уместное использование (треды всё таки внешний элемент по отношению
к нашему коду). Можно найти способ избежать его.

```python
def parallelize_db_work(
    workers: int,
    func: Callable[List[T], None],
    data_chunks: List[List[T]],
) -> None:
    with ThreadPoolExecutor(max_workers=workers) as executor:
        future_to_database = [
            executor.submit(func, chunk)
            for chunk in data_chunks
        ]
        for future in as_completed(future_to_database):
            try:
                future.result()
            except Exception as exc:
                logger.error('Generated an exception: %s' % exc)
```

Можем попробовать улучшить обработку резальтатов работы тредов при помощи
функции `wait`, которая вернет кортеж из законченных + крашнувшихся задач.
Далее мы просто логируем проблемы и возвращаем `False` если имеются неправильно
завершившиеся задачи.

```python
from concurrent.futures import ThreadPoolExecutor, wait, ALL_COMPLETED

def parallelize_db_work(
    workers: int,
    func: Callable[List[T], None],
    data_chunks: List[List[T]],
) -> bool:
    with ThreadPoolExecutor(max_workers=workers) as executor:
        futures = [
            executor.submit(func, chunk)
            for chunk in data_chunks
        ]

        done, not_done = wait(futures, return_when=ALL_COMPLETED)
        
        # Check for any failed tasks
        failed = [f for f in done if f.exception() is not None]
        if not failed:
       	    return True

        for f in failed:
            logger.error(f'Task failed with error: {f.exception()}')
        return False
```

## Пример 3

Нашёл у себя довольно странный кусочек кода, который обрабатывает полученные из кофнига значения.

```python
def main_omni_stats(
    table: str,
    date_start: Optional[dt] = None,
    date_end: Optional[dt] = None,
) -> None:
# ...

try:
    date_start = date_start or config["date_start"]
    template: str = date_end or config[conf_template]
except KeyError as e:
    logger.error(f"One of setup parameters is not set: {e}")
    sys.exit(1)
except Exception as e:
    logger.error(f"Unexpected error: {e}")
    sys.exit(1)
```

Здесь довольно легко избежать `except KeyError` на самом деле, использует `get` и
обрабатывая ошибку далее врунчную.
Вторая часть `except` на самом деле лишняя, т.к. в теории `unreachable`.

```python
date_start = date_start or config.get("date_start")
template: str = date_end or config.get(conf_template)
if not date_start:
    logger.error(f"`date_start` is not set")
    sys.exit(1)
if not template:
    logger.error(f"`template` is not set")
    sys.exit(1)
```

## Пример 4

Если мы имеем в виду, что при открытии конфига файл может отсуствовать на месте.
И мы не планируем никак пытаться продолжать работу без конфига, то `try-except` на самом
деле лишний, можно просто позволить себе крашнуться.

```python
class ConfigParserYAML:
    def __init__(self, config_file: str = "config.yaml") -> None:
        config_file_path = Path(config_file).resolve()
        try:
            with config_file_path.open('r') as configfile:
                config = yaml.safe_load(configfile)
        except FileNotFoundError:
            sys.exit(-1)
```

Просто превращается в:

```python
class ConfigParserYAML:
    def __init__(self, config_file: str = "config.yaml") -> None:
        config_file_path = Path(config_file).resolve()
        with config_file_path.open('r') as configfile:
            config = yaml.safe_load(configfile)
```

## Пример 5

Распространённая ошибка, которую я часто замечаю у себя - я оборачиваю в блок `try-catch`
взаимодействие с внешним ресурсом (чаще всего БД), что по идее приемлимо, т.к. у нас
нет полного контроля над внешним воздействием.

```python
# Здесь это ок
def execute_query(
    self, query: str, params: dict[str, Any] = {}
) -> Optional[list[tuple]]:
    if self._is_closed:
        logger.error("Trying execute query on close conn")
        return None
    with self._conn.cursor() as curs:
        try:
            curs.execute(query, params)
            return curs.fetchall()
        except (Exception, pg.DatabaseError) as error:
            logger.error(error)
            return None
```

Но затем по недоразумению, уже "обработанный" и учтённый результат также оборачивается
в аналогичный блок с `try`. Например:

```python
@app.command("/check_raw_data")
def check_raw_data_command(ack, logger, say, db):
    # Acknowledge command request
    query = RAW_DATA_QUERY
    ack("Fetching data from DB")
    try:
        result = db.execute_query(query, {})
        logger.info(result)
        say(result)
    except Exception as e:
        logger.error(e)
```

Достоверно известно, что `execute_query` возвращает либо результат, либо `None`. Достаточно:

```python
@app.command("/check_raw_data")
def check_raw_data_command(ack, logger, say, db):
    # Acknowledge command request
    query = RAW_DATA_QUERY
    ack("Fetching data from DB")
    result = db.execute_query(query, {})
    if result:
        logger.info(result)
        say(result)
        return
    logger.error(e)
```

## Выводы

Try / Catch - действительно ощущается как что-то параллельное основному потоку программы.
Но до того, как я попробовал `Go` (и чуть позже `C`) казалось, что этот способ позиционируется как вообще
единственный для обработки исключений в языках вроде `Python` и `Java`. Поэтому он
так распространён. `Go` как раз показывает, как исключения - это естественная и встроенная
в поток управления схема работы, поэтому многие разработчики вероятно как любят этот подход - он
не заставляет их думать сразу в 2-х измерениях работы программы.
Также в целом парадигма использования `try-catch` часто приводит к тому, что я перестаю
следить вообще за тем, что и где может у меня выбросить исключения, и я просто оборачиваю
кучу связанных функций подряд в большие и уродливые блоки `try`. В таких случаях конечно
здорово работают решения вроде монад `Result`, которые элегантно выстраивают "опасные"
операции в красивый конвейр с прозрачной обработкой ошибок.
